<?xml version="1.0"?>
<robot name="my_robot" xmlns:xacro="http://www.ros.org/wiki/xacro">

  <link name="base_link">
    <visual><geometry><box size="0.4 0.3 0.1"/></geometry>
      <material name="blue"><color rgba="0 0 1 1"/></material>
    </visual>
    <collision><geometry><box size="0.4 0.3 0.1"/></geometry></collision>
    <inertial><mass value="5"/><inertia ixx="0.1" iyy="0.1" izz="0.1" ixy="0" ixz="0" iyz="0"/></inertial>
  </link>

  <link name="left_wheel">
    <visual><geometry><cylinder radius="0.05" length="0.02"/></geometry><origin xyz="0 0 0" rpy="1.5708 0 0"/>
      <material name="black"><color rgba="0 0 0 1"/></material></visual>
    <collision><geometry><cylinder radius="0.05" length="0.02"/></geometry><origin xyz="0 0 0" rpy="1.5708 0 0"/></collision>
    <inertial><mass value="1"/><inertia ixx="0.01" iyy="0.01" izz="0.01" ixy="0" ixz="0" iyz="0"/></inertial>
  </link>

  <link name="right_wheel">
    <visual><geometry><cylinder radius="0.05" length="0.02"/></geometry><origin xyz="0 0 0" rpy="1.5708 0 0"/>
      <material name="black"><color rgba="0 0 0 1"/></material></visual>
    <collision><geometry><cylinder radius="0.05" length="0.02"/></geometry><origin xyz="0 0 0" rpy="1.5708 0 0"/></collision>
    <inertial><mass value="1"/><inertia ixx="0.01" iyy="0.01" izz="0.01" ixy="0" ixz="0" iyz="0"/></inertial>
  </link>

  <joint name="left_wheel_joint" type="continuous">
    <parent link="base_link"/><child link="left_wheel"/>
    <origin xyz="0 -0.15 -0.05" rpy="0 0 0"/><axis xyz="0 1 0"/>
  </joint>
  <joint name="right_wheel_joint" type="continuous">
    <parent link="base_link"/><child link="right_wheel"/>
    <origin xyz="0 0.15 -0.05" rpy="0 0 0"/><axis xyz="0 1 0"/>
  </joint>

  <link name="lidar_link">
    <visual><geometry><cylinder radius="0.05" length="0.1"/></geometry><origin xyz="0 0 0.1" rpy="0 0 0"/>
      <material name="grey"><color rgba="0.7 0.7 0.7 1"/></material></visual>
  </link>

  <joint name="lidar_joint" type="fixed">
    <parent link="base_link"/><child link="lidar_link"/><origin xyz="0 0 0.1" rpy="0 0 0"/>
  </joint>

  <gazebo reference="lidar_link">
    <sensor type="ray" name="laser_sensor">
      <update_rate>20</update_rate><pose>0 0 0 0 0 0</pose><visualize>true</visualize>
      <ray><scan><horizontal><samples>720</samples><resolution>1</resolution><min_angle>-1.5708</min_angle><max_angle>1.5708</max_angle></horizontal></scan>
        <range><min>0.12</min><max>12.0</max><resolution>0.01</resolution></range>
        <noise><type>gaussian</type><mean>0.0</mean><stddev>0.01</stddev></noise>
      </ray>
      <plugin name="gazebo_ros_laser_controller" filename="libgazebo_ros_laser.so">
        <ros><namespace>/</namespace><remapping>scan:=scan</remapping></ros>
        <topicName>scan</topicName><frameName>lidar_link</frameName>
      </plugin>
    </sensor>
  </gazebo>

  <gazebo>
    <plugin name="diff_drive" filename="libgazebo_ros_diff_drive.so">
      <ros><namespace>/</namespace><remapping>cmd_vel:=cmd_vel</remapping><remapping>odom:=odom</remapping></ros>
      <update_rate>50</update_rate>
      <left_joint>left_wheel_joint</left_joint><right_joint>right_wheel_joint</right_joint>
      <wheel_separation>0.3</wheel_separation><wheel_diameter>0.1</wheel_diameter>
      <publish_odom>true</publish_odom><publish_odom_tf>true</publish_odom_tf><publish_wheel_tf>true</publish_wheel_tf>
    </plugin>
  </gazebo>
</robot>